I'm sorry, but an uncaught exception occurred.

While running game code:
  File "game/script.rpy", line 142, in script call
    call day2morning
  File "game/day2morning.rpy", line 11, in script
    l_mom "(IN HMONG) Good morning, daughter. Your boyfriend is waiting outside for you."
Exception: Sayer 'l_mom' is not defined.

-- Full Traceback ------------------------------------------------------------

Full traceback:
  File "game/script.rpy", line 142, in script call
    call day2morning
  File "game/day2morning.rpy", line 11, in script
    l_mom "(IN HMONG) Good morning, daughter. Your boyfriend is waiting outside for you."
  File "C:\Users\Myca\programs\renpy-6.18.3-sdk\renpy\ast.py", line 573, in execute
    who = eval_who(self.who, self.who_fast)
  File "C:\Users\Myca\programs\renpy-6.18.3-sdk\renpy\ast.py", line 491, in eval_who
    raise Exception("Sayer '%s' is not defined." % who.encode("utf-8"))
Exception: Sayer 'l_mom' is not defined.

Windows-7-6.1.7601-SP1
Ren'Py 6.18.3.761
mygame 0.0
